Workbook

Sheet Nguyên tắc
A1: Nguyên tắc đặt mã sản phẩm
B3: 1 | C3: 2 | E3: 3 | F3: 4 | H3: 5 | I3: 6 | J3: 7 | K3: 8 | L3: 9 | M3: 10 | N3: 11 | P3: 12 | Q3: 13 | R3: 14 | U3: Hướng dẫn ký hiệu mỏ nào hoặc là màu sắc vẫn nên ghi chú ra.
U4: Ghi chú trong thông tin của sản phẩm.
A7: 1,2 | B7: Mã loại đá - 2 chữ cái
A8: 3,4 | B8: Mã sản phẩm - 2 số
A9: 5 | B9: Mã gia công bề mặt-1 chữ cái
A10: 6,7,8,9 | B10: Mã gia công bề cạnh-4 chữ cái/4 cạnh
A11: 10 | B11: Mã gia công đáy-1 chữ cái
A12: 11 | B12: Loại gia công khác - 1 chữ cái(không có để trống)
A13: 12,13,14 | B13: Mã kích thước - 3 số
A15: VD: | B15: B | C15: D | E15: 0 | F15: 1 | H15: E | I15: A | J15: A | K15: A | L15: A | M15: B | P15: 1 | Q15: 2 | R15: 0
B17: BD010EAAAAB120
B18: B | C18: D | E18: Đá bazan đen
E19: 0 | F19: 1 | H19: Đá lát
H20: E
I21: A | J21: A | K21: A | L21: A | M21: 4 cạnh chẻ tay
M22: B | N22: Đáy cưa
P23: 1 | Q23: 2 | R23: 0 | T23: KT 60x40x6
B24: ĐÁ LÁT BAZAN ĐEN, MẶT ĐỐT, CẠNH CHẺ TAY, ĐÁY CƯA, KT 60x40x6

Sheet Nguyên tắc Chung
A1: Nguyên tắc đặt mã sản phẩm
B3: 1 | C3: 2 | E3: 3 | G3: 4 | I3: 5 | J3: 6 | K3: 7 | L3: 8 | N3: 9 | O3: 10 | P3: 11 | Q3: 12 | S3: 13 | T3: 14 | U3: 15 | W3: 16 | X3: 17 | Y3: 18 | AD3: Hướng dẫn ký hiệu mỏ nào hoặc là màu sắc vẫn nên ghi chú ra.
F4: . | M4: - | AD4: Ghi chú trong thông tin của sản phẩm.
A6: 1,2 | B6: Nguyên vật liệu (Mã loại đá) - 2 chữ cái
A7: 3,4 | B7: Mã sản phẩm (Theo mục đích sử dụng) - 2 số
A8: 5, 6, 7 | B8: Mã gia công bề mặt chính - 3 chữ cái
A9: 8 | B9: Mã phân biệt gia công phụ - 1 số
A10: 9, 10, 11, 12 | B10: Chiều dài - 4 số mm
A11: 13, 14, 15 | B11: Chiều rộng - 3 số đối với sản phẩm đá hình hộp hoặc 2 chữ 1 số đối với sản phẩm khác (Vành, trụ, chữ L, chữ U,…)
A12: 16,17,18 | B12: Chiều cao - 3 số mm | J12: (Ký hiệu 16 sẽ đổi thành + or - trong trường hợp đá cubic lấy chiều dày dương hoặc âm)
A14: VD: | B14: B | C14: D | E14: 1 | F14: . | G14: 1 | I14: D | J14: O | K14: T | L14: 2 | M14: - | N14: 0 | O14: 6 | P14: 0 | Q14: 0 | S14: 3 | T14: 0 | U14: 0 | W14: 0 | X14: 6 | Y14: 0
B16: BD01DOT2-06004060
B17: B | C17: D | E17: Đá bazan đen
E18: 1 | F18: . | G18: 1 | I18: Đá lát …
I19: D | J19: O | K19: T | L19: Mặt đốt
L20: 2 | M20: - | N20: Cạnh chẻ tay tự nhiên
N21: 0 | O21: 6 | P21: 0 | Q21: 0 | S21: Chiều dài 600mm | U21: Chiều dài 600mm
S22: 3 | T22: 0 | U22: 0 | W22: Ký hiêụ chiều rộng 300 mm
W23: 0 | X23: 6 | Y23: 0 | Z23: Ký hiệu chiều cao 60mm
B26: BAZAN ĐEN LÁT NỀN, MẶT ĐỐT, CẠNH CHẺ TAY, ĐÁY CƯA, KT 60x30x6
A28: VD: | B28: G | C28: X | E28: 0 | F28: . | G28: 6 | I28: D | J28: O | K28: T | L28: 3 | M28: - | N28: 1 | O28: 0 | P28: 0 | Q28: 0 | S28: L | T28: 3 | U28: 5 | W28: 0 | X28: 6 | Y28: 0
B30: BX06DOT3-1000L060
B31: G | C31: X | E31: Đá Granite xám
E32: 0 | F32: . | G32: 6 | I32: Đá bo hồ bơi
I33: D | J33: O | K33: T | L33: Mặt đốt
L34: 3 | M34: - | N34: Cạnh hone
N35: 1 | O35: 0 | P35: 0 | Q35: 0 | S35: Chiều dài 1000mm | U35: Chiều dài 1000mm
S36: L | T36: 3 | U36: 5 | W36: Cắt chữ L, chiều rộng 350mm
W37: 0 | X37: 6 | Y37: 0 | Z37: Chiều cao 60mm
B40: GRANITE XÁM BO HỒ BƠI CHỮ L, MẶT ĐỐT, CẠNH DÀI TRƯỚC HONE, CÁC CẠNH CÒN LẠI CƯA, KT 1000x350x60/30 (Có bản vẽ kèm theo)
B42: Chú thích diễn giải cụ thể khi gọi tên tiếng việt:
B43: ð NGUYÊN LIỆU – TÊN SẢN PHẨM
B44: a) GIA CÔNG MẶT, CẠNH - ĐÁY (dành cho sản phẩm phổ thông, đơn giản)
B45: b) GIA CÔNG MẶT, CẠNH – ĐÁY – MÉP – GIA CÔNG KHÁC – HÌNH VẼ CÓ HOẶC KHÔNG (mô tả chi tiết dành cho sản phẩm cao cấp, phức tạp, nên hình dung các sản phẩm mô tả đầy đủ như thế này)
B46: Ví dụ:
B47: a) Sản phẩm phổ thông:
B48: Bazan xám Cubic, mặt và các cạnh Chẻ tay
B49: Blue stone Lát nền, mặt và các cạnh Quay mẻ
B50: Bazan đen Lát nền, mặt Đốt, cạnh Chẻ tay, đáy Cưa
B51: b) Sản phẩm cao cấp, chi tiết, phức tạp:
...

Sheet Import data
A2: No | B2: Product_Code | C2: Type1 | D2: Type2 | E2: Description | F2: Long | G2: Width | H2: High | I2: PeciesPerCrate | J2: Crate | K2: WeightRate | L2: OtherRate | M2: Remarks
A3: 1 | B3: BD04DOT1-10003015 | C3: BAZAN ĐEN | D3: Bậc thang | E3: BAZAN ĐEN, Bậc thang-5 mặt đốt xịt nước, vạt mép 3mm KT 100x35x15 SL:10 v/k | F3: 100 | G3: 35 | H3: 15 | I3: 10 | K3: 3
A4: 2 | B4: BD04DOT2-10003015 | C4: BAZAN ĐEN | D4: Bậc thang | E4: BAZAN ĐEN, Bậc thang-5 mặt đốt xịt nước, vạt mép 3mm KT 100x35x15 SL:5 v/k | F4: 100 | G4: 35 | H4: 15 | I4: 5 | K4: 3
A5: 3 | B5: BD04DOT1-12503015 | C5: BAZAN ĐEN | D5: Bậc thang | E5: BAZAN ĐEN, Bậc thang-5 mặt đốt xịt nước, vạt mép 3mm KT 125x35x15 SL:8 v/k | F5: 125 | G5: 35 | H5: 15 | I5: 8 | K5: 3
A6: 4 | B6: BD04DOT1-15003015 | C6: BAZAN ĐEN | D6: Bậc thang | E6: BAZAN ĐEN, Bậc thang-5 mặt đốt xịt nước, vạt mép 3mm KT 150x35x15 SL:6 v/k | F6: 150 | G6: 35 | H6: 15 | I6: 6 | K6: 3
A7: 5 | B7: BD04DOT1-07503015 | C7: BAZAN ĐEN | D7: Bậc thang | E7: BAZAN ĐEN, Bậc thang-5 mặt đốt xịt nước, vạt mép 3mm KT 75x35x15 SL:10 v/k | F7: 75 | G7: 35 | H7: 15 | I7: 10 | K7: 3
A8: 6 | B8: BD04DOT1-10001080 | C8: BAZAN ĐEN | D8: Bậc thang | E8: BAZAN ĐEN, Bậc thang-6 mặt đốt xịt nước, vạt mép cạnh dài 5mm, vạt mép cạnh ngắn 3mm KT 100x10x8 SL:42 v/k | F8: 100 | G8: 10 | H8: 8 | I8: 42 | K8: 3
A9: 7 | B9: BD04DOT1-10001120 | C9: BAZAN ĐEN | D9: Bậc thang | E9: BAZAN ĐEN, Bậc thang-6 mặt đốt xịt nước, vạt mép 3mm KT 100x12x12 SL:32 v/k | F9: 100 | G9: 12 | H9: 12 | I9: 32 | K9: 3
A10: 8 | B10: BD04DOT1-10005080 | C10: BAZAN ĐEN | D10: Bậc thang | E10: BAZAN ĐEN, Bậc thang-6 mặt đốt xịt nước, vạt mép cạnh dài 5mm, vạt mép cạnh ngắn 3mm KT 100x15x8 SL:12 v/k | F10: 100 | G10: 15 | H10: 8 | I10: 12 | K10: 3
A11: 9 | B11: BD03DOT1-10002080 | C11: BAZAN ĐEN | D11: Đá cây | E11: BAZAN ĐEN, Đá cây-6 mặt đốt xịt nước, vạt mép cạnh dài 5mm, vạt mép cạnh ngắn 3mm KT 100x20x8 SL:20 v/k | F11: 100 | G11: 20 | H11: 8 | I11: 20 | K11: 3
A12: 10 | B12: BD04DOT3-10003150 | C12: BAZAN ĐEN | D12: Bậc thang | E12: BAZAN ĐEN, Bậc thang-6 mặt đốt xịt nước, vạt mép cạnh dài 5mm, vạt mép cạnh ngắn 3mm KT 100x35x15 SL:10 v/k | F12: 100 | G12: 35 | H12: 15 | I12: 10 | K12: 3
A13: 11 | B13: BD04DOT1-10003150 | C13: BAZAN ĐEN | D13: Bậc thang | E13: BAZAN ĐEN, Bậc thang-6 mặt đốt xịt nước, vạt mép cạnh dài 5mm, vạt mép cạnh ngắn 3mm KT 100x35x15 SL:5 v/k | F13: 100 | G13: 35 | H13: 15 | I13: 5 | K13: 3
A14: 12 | B14: BD04DOT2-10003150 | C14: BAZAN ĐEN | D14: Bậc thang | E14: BAZAN ĐEN, Bậc thang-6 mặt đốt xịt nước, vạt mép cạnh dài 5mm, vạt mép cạnh ngắn 3mm KT 100x35x15 SL:8 v/k | F14: 100 | G14: 35 | H14: 15 | I14: 8 | K14: 3
... A78: 76 | B78: BD01DOT1-08004040 | C78: BAZAN ĐEN | D78: Đá lát | E78: BAZAN ĐEN, Đá lát-6 mặt đốt xịt nước, vạt mép 3mm KT 80x40x4 SL:20 v/k | F78: 80 | G78: 40 | H78: 4 | I78: 20 | K78: 3
A79: 77 | B79: BD01DOT1-01401060 | C79: BAZAN ĐEN | D79: Đá lát | E79: BAZAN ĐEN, Đá lát-Mặt đốt xịt nước, cạnh cưa, vạt mép 3mm KT 14-18-22x12x6 SL:192 v/k 64v Mỗi loại | F79: 18 | G79: 12 | H79: 6 | I79: 192 | K79: 3 | M79: (14x64, 18x64, 22x64)
A80: 78 | B80: BD06DOT1-01501012 | C80: BAZAN ĐEN | D80: Đá lát | E80: BAZAN ĐEN, Đá lát-Mặt đốt xịt nước, cạnh cưa KT 15x15x1.2 SL:250 v/k | F80: 15 | G80: 15 | H80: 1.2 | I80: 250 | K80: 3
A81: 79 | B81: BD01DOT1-02001030 | C81: BAZAN ĐEN | D81: Đá lát | E81: BAZAN ĐEN, Đá lát-Mặt đốt xịt nước, cạnh cưa, vạt mép 3mm KT 20x10x3 SL:660 v/k | F81: 20 | G81: 10 | H81: 3 | I81: 660 | K81: 3
A82: 80 | B82: BD01DOT1-03501060 | C82: BAZAN ĐEN | D82: Đá lát | E82: BAZAN ĐEN, Đá lát-Mặt đốt xịt nước, cạnh cưa, vạt mép 3mm KT 35x15x6 SL:128 v/k | F82: 35 | G82: 15 | H82: 6 | I82: 128 | K82: 3
A83: 81 | B83: BD01DOT1-06003030 | C83: BAZAN ĐEN | D83: Đá lát | E83: BAZAN ĐEN, Đá lát-Mặt đốt xịt nước, cạnh cưa, vạt mép 3mm KT 60x30x3 SL:68 v/k | F83: 60 | G83: 30 | H83: 3 | I83: 68 | K83: 3
A84: 82 | B84: BD01DOT1-06004030 | C84: BAZAN ĐEN | D84: Đá lát | E84: BAZAN ĐEN, Đá lát-Mặt đốt xịt nước, cạnh cưa, vạt mép 3mm KT 60x40x3 SL:34 v/k | F84: 60 | G84: 40 | H84: 3 | I84: 34 | K84: 3
A85: 83 | B85: BD01DOT1-06006030 | C85: BAZAN ĐEN | D85: Đá lát | E85: BAZAN ĐEN, Đá lát-Mặt đốt xịt nước, cạnh cưa, vạt mép 1mm KT 60x60x3 SL:34 v/k | F85: 60 | G85: 60 | H85: 3 | I85: 34 | K85: 3
A86: 84 | B86: BD01DOT1-08003030 | C86: BAZAN ĐEN | D86: Đá lát | E86: BAZAN ĐEN, Đá lát-Mặt đốt xịt nước, cạnh cưa, vạt mép 3mm KT 80x30x3 SL:34 v/k | F86: 80 | G86: 30 | H86: 3 | I86: 34 | K86: 3
A87: 85 | B87: BD01DOT1-08004030 | C87: BAZAN ĐEN | D87: Đá lát | E87: BAZAN ĐEN, Đá lát-Mặt đốt xịt nước, cạnh cưa, vạt mép 3mm KT 80x40x3 SL:34 v/k | F87: 80 | G87: 40 | H87: 3 | I87: 34 | K87: 3
A88: 86 | B88: BD01DOT1-09004030 | C88: BAZAN ĐEN | D88: Đá lát | E88: BAZAN ĐEN, Đá lát-Mặt đốt xịt nước, cạnh cưa, vạt mép 3mm KT 90x45x3 SL:30 v/k | F88: 90 | G88: 45 | H88: 3 | I88: 30 | K88: 3
A89: 87 | B89: BD01DOT1-09006030 | C89: BAZAN ĐEN | D89: Đá lát | E89: BAZAN ĐEN, Đá lát-Mặt đốt xịt nước, cạnh cưa, vạt mép 3mm KT 90x60x3 SL:20 v/k | F89: 90 | G89: 60 | H89: 3 | I89: 20 | K89: 3
A90: 88 | B90: BD01DOT2-09006030 | C90: BAZAN ĐEN | D90: Đá lát | E90: BAZAN ĐEN, Đá lát-Mặt đốt xịt nước, cạnh cưa, vạt mép 1mm KT 90x60x3 SL:25 v/k | F90: 90 | G90: 60 | H90: 3 | I90: 25 | K90: 3
A91: 89 | B91: BD08DOT1-22006030 | C91: BAZAN ĐEN | D91: Đá tấm | E91: BAZAN ĐEN, Đá tấm-Đốt xịt nước KT 150-220x60x3 SL:20 v/k | F91: 220 | G91: 60 | H91: 3 | I91: 20 | K91: 3
... A129: 127 | B129: BL01GCR1-02001050 | C129: BLUESTONE | D129: Cubic | E129: BLUESTONE, Cubic-Giả cổ rung KT 20x10x5 SL:360 v/k | F129: 20 | G129: 10 | H129: 5 | I129: 360 | K129: 2.7
A130: 128 | B130: BL09GCR1-01956020 | C130: BLUESTONE | D130: Đá bộ | E130: BLUESTONE, Đá bộ-Giả cổ rung bộ KT 19.5-60x19.5-40x2 SL:132 v/k (19.5x19.5=44, 39.7x19.5=22, 40x40=44, 60x40=22 v) | F130: 40 | G130: 29.5 | H130: 2 | I130: 132 | K130: 2.7 | M130: (19.5-19.5x44, 39.7-19.5x22, 40-40x44, 60-40x22)
A131: 129 | B131: BL09GCR1-02002060 | C131: BLUESTONE | D131: Đá bộ | E131: BLUESTONE, Đá bộ-Giả cổ rung bộ KT 20-30-40x20x6 SL:80 v/k (20=20, 30=30, 40=30 v) | F131: 31.25 | G131: 20 | H131: 6 | I131: 80 | K131: 2.7 | M131: (20x20, 30x30, 40x30)
A132: 130 | B132: BL09GCT1-01956025 | C132: BLUESTONE | D132: Đá bộ | E132: BLUESTONE, Đá bộ-Giả cổ tay bộ KT 19.5-60x19.5-40x2.5 SL:108 v/k (19.5x19.5=36, 39.7x19.5=18, 40x40=36, 60x40=18 v) | F132: 40 | G132: 29.5 | H132: 2.5 | I132: 108 | K132: 2.7 | M132: (19.5-19.5x36, 39.7-19.5x18, 40-40x36, 60-40x18)
A133: 131 | B133: BL09GCT1-02976030 | C133: BLUESTONE | D133: Đá bộ | E133: BLUESTONE, Đá bộ-Giả cổ tay bộ KT 29.7-60x29.7-60x3 SL:50 v/k (60x60=20, 60x29.7=10, 29.7x29.7=20 v) | F133: 48 | G133: 30 | H133: 3 | I133: 50 | K133: 2.7 | M133: (60-60x20, 60-29.7x10, 29.7-29.7x20)
A134: 132 | B134: BL03GCR1-06003050 | C134: BLUESTONE | D134: Đá cây | E134: BLUESTONE, Đá cây-Giả cổ rung mặt và cạnh KT 60x30x5 SL:40 v/k | F134: 60 | G134: 30 | H134: 5 | I134: 40 | K134: 2.7
A135: 133 | B135: BL03GCT1-10001050 | C135: BLUESTONE | D135: Đá cây | E135: BLUESTONE, Đá cây-Giả cổ tay KT 100x15x5 SL:48 v/k | F135: 100 | G135: 15 | H135: 5 | I135: 48 | K135: 2.7
A136: 134 | B136: BL03GCT1-10002050 | C136: BLUESTONE | D136: Đá cây | E136: BLUESTONE, Đá cây-Giả cổ tay KT 100x20x5 SL:36 v/k | F136: 100 | G136: 20 | H136: 5 | I136: 36 | K136: 2.7
A137: 135 | B137: BL03GCT1-10002100 | C137: BLUESTONE | D137: Đá cây | E137: BLUESTONE, Đá cây-Giả cổ tay KT 100x25x10 SL:16 v/k | F137: 100 | G137: 25 | H137: 10 | I137: 16 | K137: 2.7
A138: 136 | B138: BL03GCT1-10003050 | C138: BLUESTONE | D138: Đá cây | E138: BLUESTONE, Đá cây-Giả cổ tay KT 100x30x5 SL:24 v/k | F138: 100 | G138: 30 | H138: 5 | I138: 24 | K138: 2.7
A139: 137 | B139: BL03GCT1-10005050 | C139: BLUESTONE | D139: Đá cây | E139: BLUESTONE, Đá cây-Giả cổ tay KT 100x35x5 SL:20 v/k | F139: 100 | G139: 35 | H139: 5 | I139: 20 | K139: 2.7
A140: 138 | B140: BL03GCT1-12502100 | C140: BLUESTONE | D140: Đá cây | E140: BLUESTONE, Đá cây-Giả cổ tay KT 125x25x10 SL:14 v/k | F140: 125 | G140: 25 | H140: 10 | I140: 14 | K140: 2.7
A141: 139 | B141: BL03GCT1-05002100 | C141: BLUESTONE | D141: Đá cây | E141: BLUESTONE, Đá cây-Giả cổ tay KT 50x25x10 SL:32 v/k | F141: 50 | G141: 25 | H141: 10 | I141: 32 | K141: 2.7
...

Sheet Mã NVL, SP, Gia công
A1: Nguyên vật liệu | B1: English | C1: Mô tả | E1: Mục đích sử dụng | F1: Mô tả | H1: Ký hiệu | I1: Nhóm mã gia công chính | J1: English | K1: Tên gọi khác | M1: Ký hiệu | N1: Gia công phụ | P1: Ký hiệu | Q1: Sản phẩm đặc biệt | S1: Mã gia công bề mặt | T1: Mô tả | V1: Mã gia công cạnh | W1: Mô tả
A2: MB | B2: Bluestone | C2: Bluestone | E2: 01 | F2: Đá lát nền ngoại thất (Cubic, tấm, lát từ 2.5cm) | H2: CUA | I2: Cưa | J2: Sawn | M2: 0 | N2: Không có gia công phụ | P2: L | Q2: Cắt chữ L | S2: 00 | T2: Không yêu cầu | V2: 00 | W2: Không yêu cầu
A3: MT | B3: White Marble | C3: Marble Trắng | E3: 02 | F3: Tường rào (Đá khối, nắp tường rào, ốp tường rào) | H3: DOT | I3: Đốt | J3: Flamed | K3: Khò lửa | M3: 1 | N3: Cạnh cưa | P3: U | Q3: Cắt chữ U | S3: 01 | T3: Mặt đốt | V3: 01 | W3: Cạnh đốt
A4: MV | B4: Yellow Marble | C4: Marble Vàng | E4: 03 | F4: Đá cây | H4: DOC | I4: Đốt chải | J4: Flamed brush | K4: Đốt chải máy | M4: 2 | N4: Cạnh đốt | P4: G | Q4: Cắt góc độ | S4: 02 | T4: Mặt đốt, đáy cưa | V4: 02 | W4: Cạnh cưa
A5: BT | B5: Hive Basalt | C5: Bazan tổ ong | E5: 04 | F5: Đá bậc thang (Nguyên khối, ốp BT) | H5: DOX | I5: Đốt xịt | J5: Flamed... water | K5: Đốt xịt nước | M5: 3 | N5: Cạnh chẻ tay tự nhiên | P5: C | Q5: Cắt vòng cung | S5: 03 | T5: Mặt đốt, đáy băm | V5: 03 | W5: Cạnh cưa, vạt mép 1mm
A6: BX | B6: Grey Basalt | C6: Bazan Xám | E6: 05 | F6: Đá mỹ nghệ | H6: HON | I6: Hone | J6: Honed | K6: Mài mờ | M6: 4 | N6: Cạnh hone | P6: K | Q6: Lỗ khoan | S6: 04 | T6: 2 mặt đốt | V6: 04 | W6: Cạnh cưa, vạt mép 2mm
A7: BD | B7: Black Basalt | C7: Bazan Đen | E7: 06 | F7: Cao cấp hồ bơi, bộ cửa | H7: CTA | I7: Chẻ tay tự nhiên | J7: split, Handmade | K7: Sộ cạnh tự nhiên, bóc mặt | M7: 5 | N7: Cạnh bo tròn R | P7: T | Q7: Hình trụ | S7: 05 | T7: 5 mặt đốt | V7: 05 | W7: Cạnh cưa, vạt mép 3mm
A8: GX | B8: Grey Granite | C8: Granite Xám | E8: 07 | F8: Lát nền bên trong, đá bộ | H8: CLO | I8: Cưa lột tay | J8: sawn then cleaved | K8: Cưa bóc mặt | M8: 6 | N8: Cạnh gõ mẻ | P8: B | Q8: Đá bộ | S8: 06 | T8: 5 mặt đốt, đáy cưa | V8: 06 | W8: Vạt mép cạnh dài 5mm, vạt mép cạnh ngắn 3mm
A9: GT | B9: White Granite | C9: Granite Trắng | E9: 08 | F9: Ốp tường | H9: TDE | I9: Tẩy đẹp | J9: chiseled | M9: 7 | N9: Cạnh băm | P9: V | Q9: Đá vành | S9: 07 | T9: 6 mặt đốt | V9: 07 | W9: Mài giấy 5 cạnh, vạt mép cạnh dài 3mm, vạt mép cạnh ngắn 1mm
A10: GV | B10: Yellow Granite | C10: Granite Vàng | E10: 09 | F10: Slab, bàn bếp, cao cấp | H10: GCR | I10: Giả cổ rung | J10: vibrated honed tumbled | K10: Giả cổ máy, Chà sỏi | M10: 8 | N10: Đáy băm | S10: 08 | T10: Mặt đốt xịt nước | V10: 08 | W10: Cạnh chẻ tay
A11: GD | B11: Red Granite | C11: Granite Đỏ | H11: GCT | I11: Giả cổ tay | J11: Old Imitation | M11: 9 | N11: GC Khác (Có chú thích) | S11: 10 | T11: 2 mặt đốt xịt nước | V11: 10 | W11: Cạnh tẩy tay
A12: GH | B12: Pink Granite | C12: Granite Hồng | H12: MGI | I12: Mài giấy | J12: Scraped | S12: 11 | T12: 5 mặt đốt xịt nước | V12: 11 | W12: Cạnh tẩy đẹp
H13: PCA | I13: Phun cát | J13: Sandblasted | K13: Xịt cát | S13: 12 | T13: 5 mặt đốt xịt nước, đáy cưa | V13: 12 | W13: Cạnh sộ tay
H14: MCA | I14: Mài cát | J14: Sandblasted | S14: 13 | T14: 6 mặt đốt xịt nước | V14: 13 | W14: Cạnh giả cổ rung
H15: QME | I15: Quay mẻ | J15: tumbled | S15: 14 | T15: Mặt đốt chải 1 lần | V15: 14 | W15: 1 cạnh dài đốt, còn lại cưa, vạt mép 2mm
H16: TLO | I16: Tách lồi | J16: Cleaved | K16: Đục lồi
H17: BON | I17: Bóng | J17: polished | S17: 15 | T17: Mặt đốt chải 2 lần | V17: 15 | W17: 1 cạnh dài đốt, vạt mép 3mm, các cạnh còn lại cưa
H18: BAM | I18: Băm | J18: bush hammere | S18: 18 | T18: Mặt băm, đáy cưa | V18: 18 | W18: 1 cạnh dài đốt xịt nước bo tròn, cạnh còn lại vạt mép 3mm
H19: CHA | I19: Chải | J19: brush | S19: 19 | T19: 2 mặt băm | V19: 19 | W19: 1 cạnh dài đốt bo tròn, các cạnh còn lại cưa
S20: 20 | T20: 4 mặt băm | V20: 20 | W20: 1 cạnh dài đốt chải 2 lần bo tròn
H21: (1 Chữ: 3 kí tự đầu 2 Chữ: kí tự đầu chữ 1 + 2 kí tự đầu chữ 2 3 Chữ: 3 kí tự đầu của 3 chữ) 4 Chữ: kí tự đầu chữ 1 + 2 kí tự đầu chữ 2) | S21: 21 | T21: Mặt cưa, đáy cưa | V21: 21 | W21: 1 cạnh dài hon
S22: 22 | T22: Cưa 2 mặt | V22: 22 | W22: 1 cạnh dài hon, vạt mép 3mm
S23: 23 | T23: Cưa lột tay | V23: 23 | W23: 1 cạnh dài hon, mép trên và dưới của cạnh hon vạt 3mm
S24: 24 | T24: Mài giấy | V24: 24 | W24: 1 cạnh dài giả cổ rung, vạt mép 3mm, các cạnh còn lại cưa máy
S25: 25 | T25: Mài giấy, đáy cưa | V25: 25 | W25: 1 cạnh dài mài giấy, vạt mép 3mm
S26: 26 | T26: Mài giấy 6 mặt | V26: 26 | W26: 1 cạnh dài chẻ tay tự nhiên, còn lại cưa
S27: 27 | T27: Mặt hon | V27: 27 | W27: 1 cạnh ngắn đốt, các cạnh còn lại cưa, vạt mép 3mm
S28: 28 | T28: Mặt phun cát | V28: 28 | W28: 2 cạnh dài đốt, vạt mép 2mm
S29: 29 | T29: Mặt tẩy đẹp | V29: 29 | W29: 2 cạnh dài đốt xịt nước, vạt 4 mép cạnh dài 3mm
S30: 30 | T30: Mặt tẩy đẹp, đáy cưa | V30: 30 | W30: 2 cạnh dài hon, 2 mép dài trên bo tròn, 2 mép dài dưới vạt 3mm
S31: 31 | T31: Tẩy đẹp 5 mặt | V31: 31 | W31: 2 cạnh dài hon, vạt 4 mép cạnh dài 3mm
S32: 32 | T32: Tẩy đẹp 6 mặt | V32: 32 | W32: 2 cạnh dài mài giấy, vạt mép trên và mép dưới 2 cạnh dài 3mm
S33: 33 | T33: Chẻ tay tự nhiên | V33: 33 | W33: 2 cạnh dài chẻ tay tự nhiên
... S37: 37 | T37: Mẻ cát, giả cổ rung | V37: 37 | W37: 5 cạnh bo tròn, cạnh còn lại cưa
S38: 38 | T38: Mẻ cát CLC
S39: 39 | T39: Quay mẻ
S40: 40 | T40: Quay mẻ CLC
S41: 41 | T41: Tách lồi

Sheet Ma SP
A2: NO | B2: Product Code | C2: Stone | E2: Product | F2: Mô tả | H2: L | I2: W | J2: H | K2: Packing | L2: Remark
A3: 3 | B3: BD04DOX0-125035150 | C3: BAZAN ĐEN | D3: 04 | E3: Bậc thang | F3: BAZAN ĐEN, Bậc thang-6 mặt đốt xịt nước, vạt mép cạnh dài 6mm, vạt mép cạnh ngắn 4mm. | G3: =H3&I3&J3 -> 1253515 | H3: 125 | I3: 35 | J3: 15 | K3: 8
A4: 4 | B4: BD04DOX0-150035150 | C4: BAZAN ĐEN | D4: 04 | E4: Bậc thang | F4: BAZAN ĐEN, Bậc thang-6 mặt đốt xịt nước, vạt mép cạnh dài 6mm, vạt mép cạnh ngắn 4mm. | G4: =H4&I4&J4 -> 1503515 | H4: 150 | I4: 35 | J4: 15 | K4: 6
A5: 5 | B5: BD04DOX0-075035150 | C5: BAZAN ĐEN | D5: 04 | E5: Bậc thang | F5: BAZAN ĐEN, Bậc thang-6 mặt đốt xịt nước, vạt mép cạnh dài 6mm, vạt mép cạnh ngắn 4mm. | G5: =H5&I5&J5 -> 753515 | H5: 75 | I5: 35 | J5: 15 | K5: 10
A6: 6 | B6: BD04DOX0-100010080 | C6: BAZAN ĐEN | D6: 04 | E6: Bậc thang | F6: BAZAN ĐEN, Bậc thang-6 mặt đốt xịt nước, vạt mép cạnh dài 6mm, vạt mép cạnh ngắn 4mm. | G6: =H6&I6&J6 -> 100108 | H6: 100 | I6: 10 | J6: 8 | K6: 42
A7: 7 | B7: BD04DOT0-10001120 | C7: BAZAN ĐEN | D7: 04 | E7: Bậc thang | F7: BAZAN ĐEN, Bậc thang-6 mặt đốt xịt nước, vạt mép 3mm | G7: =H7&I7&J7 -> 1001212 | H7: 100 | I7: 12 | J7: 12 | K7: 32
A8: 8 | B8: BD04DOT0-10005080 | C8: BAZAN ĐEN | D8: 04 | E8: Bậc thang | F8: BAZAN ĐEN, Bậc thang-6 mặt đốt xịt nước, vạt mép cạnh dài 5mm, vạt mép cạnh ngắn 3mm KT 100x15x8 SL:12 v/k | G8: =H8&I8&J8 -> 100158 | H8: 100 | I8: 15 | J8: 8 | K8: 12
A9: 9 | B9: BD03DOT0-10002080 | C9: BAZAN ĐEN | D9: 03 | E9: Đá cây | F9: BAZAN ĐEN, Đá cây-6 mặt đốt xịt nước, vạt mép cạnh dài 5mm, vạt mép cạnh ngắn 3mm KT 100x20x8 SL:20 v/k | G9: =H9&I9&J9 -> 100208 | H9: 100 | I9: 20 | J9: 8 | K9: 20
A10: 10 | B10: BD04CTA2-100035150 | C10: BAZAN ĐEN | D10: 04 | E10: Bậc thang | F10: BAZAN ĐEN, Bậc thang-Mặt trước chẻ tay tự nhiên, các cạnh còn lại đốt xịt nước, vạt mép cạnh dài 6mm, vạt mép cạnh ngắn 4mm. | G10: =H10&I10&J10 -> 1003515 | H10: 100 | I10: 35 | J10: 15 | K10: 10
A11: 13 | B11: BD04DOT0-12003150 | C11: BAZAN ĐEN | D11: 04 | E11: Bậc thang | F11: BAZAN ĐEN, Bậc thang-6 mặt đốt xịt nước, vạt mép cạnh dài 5mm, vạt mép cạnh ngắn 3mm KT 120x35x15 SL:8 v/k | G11: =H11&I11&J11 -> 1203515 | H11: 120 | I11: 35 | J11: 15 | K11: 8
A12: 14 | B12: BD04CTA2-125035150 | C12: BAZAN ĐEN | D12: 04 | E12: Bậc thang | F12: BAZAN ĐEN, Bậc thang-Mặt trước chẻ tay tự nhiên, các cạnh còn lại đốt chải, vạt mép cạnh dài 6mm, vạt mép cạnh ngắn 4mm. | G12: =H12&I12&J12 -> 1253515 | H12: 125 | I12: 35 | J12: 15 | K12: 8
A13: 16 | B13: BD04DOT1-15001120 | C13: BAZAN ĐEN | D13: 04 | E13: Bậc thang | F13: BAZAN ĐEN, Bậc thang-6 mặt đốt xịt nước, vạt mép 3mm KT 150x12x12 SL:24 v/k | G13: =H13&I13&J13 -> 1501212 | H13: 150 | I13: 12 | J13: 12 | K13: 24
A14: 17 | B14: BD04CTA2-150035150 | C14: BAZAN ĐEN | D14: 04 | E14: Bậc thang | F14: BAZAN ĐEN, Bậc thang-Mặt trước chẻ tay tự nhiên, các cạnh còn lại đốt chải, vạt mép cạnh dài 6mm, vạt mép cạnh ngắn 4mm. | G14: =H14&I14&J14 -> 1503515 | H14: 150 | I14: 35 | J14: 15 | K14: 6
... A72: 76 | B72: BD01DOT1-08004040 | C72: BAZAN ĐEN | D72: 01 | E72: Đá lát | F72: BAZAN ĐEN, Đá lát-6 mặt đốt xịt nước, vạt mép 3mm KT 80x40x4 SL:20 v/k | G72: =H72&I72&J72 -> 80404 | H72: 80 | I72: 40 | J72: 4 | K72: 20
A73: 77 | B73: BD01DOT1-01401060 | C73: BAZAN ĐEN | D73: 01 | E73: Đá lát | F73: BAZAN ĐEN, Đá lát-Mặt đốt xịt nước, cạnh cưa, vạt mép 3mm KT 14-18-22x12x6 SL:192 v/k 64v Mỗi loại | G73: =H73&I73&J73 -> 18126 | H73: 18 | I73: 12 | J73: 6 | K73: 192 | L73: (14x64, 18x64, 22x64)
A74: 78 | B74: BD06DOT1-01501012 | C74: BAZAN ĐEN | D74: 06 | E74: Đá lát | F74: BAZAN ĐEN, Đá lát-Mặt đốt xịt nước, cạnh cưa KT 15x15x1.2 SL:250 v/k | G74: =H74&I74&J74 -> 15151.2 | H74: 15 | I74: 15 | J74: 1.2 | K74: 250
A75: 79 | B75: BD01DOT1-02001030 | C75: BAZAN ĐEN | D75: 01 | E75: Đá lát | F75: BAZAN ĐEN, Đá lát-Mặt đốt xịt nước, cạnh cưa, vạt mép 3mm KT 20x10x3 SL:660 v/k | G75: =H75&I75&J75 -> 20103 | H75: 20 | I75: 10 | J75: 3 | K75: 660
A76: 80 | B76: BD01DOT1-03501060 | C76: BAZAN ĐEN | D76: 01 | E76: Đá lát | F76: BAZAN ĐEN, Đá lát-Mặt đốt xịt nước, cạnh cưa, vạt mép 3mm KT 35x15x6 SL:128 v/k | G76: =H76&I76&J76 -> 35156 | H76: 35 | I76: 15 | J76: 6 | K76: 128
A77: 81 | B77: BD01DOT1-06003030 | C77: BAZAN ĐEN | D77: 01 | E77: Đá lát | F77: BAZAN ĐEN, Đá lát-Mặt đốt xịt nước, cạnh cưa, vạt mép 3mm KT 60x30x3 SL:68 v/k | G77: =H77&I77&J77 -> 60303 | H77: 60 | I77: 30 | J77: 3 | K77: 68
A78: 82 | B78: BD01DOT1-06004030 | C78: BAZAN ĐEN | D78: 01 | E78: Đá lát | F78: BAZAN ĐEN, Đá lát-Mặt đốt xịt nước, cạnh cưa, vạt mép 3mm KT 60x40x3 SL:34 v/k | G78: =H78&I78&J78 -> 60403 | H78: 60 | I78: 40 | J78: 3 | K78: 34
A79: 83 | B79: BD01DOT1-06006030 | C79: BAZAN ĐEN | D79: 01 | E79: Đá lát | F79: BAZAN ĐEN, Đá lát-Mặt đốt xịt nước, cạnh cưa, vạt mép 1mm KT 60x60x3 SL:34 v/k | G79: =H79&I79&J79 -> 60603 | H79: 60 | I79: 60 | J79: 3 | K79: 34
A80: 84 | B80: BD01DOT1-08003030 | C80: BAZAN ĐEN | D80: 01 | E80: Đá lát | F80: BAZAN ĐEN, Đá lát-Mặt đốt xịt nước, cạnh cưa, vạt mép 3mm KT 80x30x3 SL:34 v/k | G80: =H80&I80&J80 -> 80303 | H80: 80 | I80: 30 | J80: 3 | K80: 34
A81: 85 | B81: BD01DOT1-08004030 | C81: BAZAN ĐEN | D81: 01 | E81: Đá lát | F81: BAZAN ĐEN, Đá lát-Mặt đốt xịt nước, cạnh cưa, vạt mép 3mm KT 80x40x3 SL:34 v/k | G81: =H81&I81&J81 -> 80403 | H81: 80 | I81: 40 | J81: 3 | K81: 34
A82: 86 | B82: BD01DOT1-09004030 | C82: BAZAN ĐEN | D82: 01 | E82: Đá lát | F82: BAZAN ĐEN, Đá lát-Mặt đốt xịt nước, cạnh cưa, vạt mép 3mm KT 90x45x3 SL:30 v/k | G82: =H82&I82&J82 -> 90453 | H82: 90 | I82: 45 | J82: 3 | K82: 30
A83: 87 | B83: BD01DOT1-09006030 | C83: BAZAN ĐEN | D83: 01 | E83: Đá lát | F83: BAZAN ĐEN, Đá lát-Mặt đốt xịt nước, cạnh cưa, vạt mép 3mm KT 90x60x3 SL:20 v/k | G83: =H83&I83&J83 -> 90603 | H83: 90 | I83: 60 | J83: 3 | K83: 20
A84: 88 | B84: BD01DOT2-09006030 | C84: BAZAN ĐEN | D84: 01 | E84: Đá lát | F84: BAZAN ĐEN, Đá lát-Mặt đốt xịt nước, cạnh cưa, vạt mép 1mm KT 90x60x3 SL:25 v/k | G84: =H84&I84&J84 -> 90603 | H84: 90 | I84: 60 | J84: 3 | K84: 25
A85: 89 | B85: BD08DOT1-22006030 | C85: BAZAN ĐEN | D85: 08 | E85: Đá tấm | F85: BAZAN ĐEN, Đá tấm-Đốt xịt nước KT 150-220x60x3 SL:20 v/k | G85: =H85&I85&J85 -> 220603 | H85: 220 | I85: 60 | J85: 3 | K85: 20
... A123: 127 | B123: BL01GCR1-02001050 | C123: BLUESTONE | D123: 01 | E123: Cubic | F123: BLUESTONE, Cubic-Giả cổ rung KT 20x10x5 SL:360 v/k | G123: =H123&I123&J123 -> 20105 | H123: 20 | I123: 10 | J123: 5 | K123: 360
A124: 128 | B124: BL09GCR1-01956020 | C124: BLUESTONE | D124: 09 | E124: Đá bộ | F124: BLUESTONE, Đá bộ-Giả cổ rung bộ KT 19.5-60x19.5-40x2 SL:132 v/k (19.5x19.5=44, 39.7x19.5=22, 40x40=44, 60x40=22 v) | G124: =H124&I124&J124 -> 4029.52 | H124: 40 | I124: 29.5 | J124: 2 | K124: 132 | L124: (19.5-19.5x44, 39.7-19.5x22, 40-40x44, 60-40x22)
A125: 129 | B125: BL09GCR1-02002060 | C125: BLUESTONE | D125: 09 | E125: Đá bộ | F125: BLUESTONE, Đá bộ-Giả cổ rung bộ KT 20-30-40x20x6 SL:80 v/k (20=20, 30=30, 40=30 v) | G125: =H125&I125&J125 -> 31.25206 | H125: 31.25 | I125: 20 | J125: 6 | K125: 80 | L125: (20x20, 30x30, 40x30)
A126: 130 | B126: BL09GCT1-01956025 | C126: BLUESTONE | D126: 09 | E126: Đá bộ | F126: BLUESTONE, Đá bộ-Giả cổ tay bộ KT 19.5-60x19.5-40x2.5 SL:108 v/k (19.5x19.5=36, 39.7x19.5=18, 40x40=36, 60x40=18 v) | G126: =H126&I126&J126 -> 4029.52.5 | H126: 40 | I126: 29.5 | J126: 2.5 | K126: 108 | L126: (19.5-19.5x36, 39.7-19.5x18, 40-40x36, 60-40x18)
A127: 131 | B127: BL09GCT1-02976030 | C127: BLUESTONE | D127: 09 | E127: Đá bộ | F127: BLUESTONE, Đá bộ-Giả cổ tay bộ KT 29.7-60x29.7-60x3 SL:50 v/k (60x60=20, 60x29.7=10, 29.7x29.7=20 v) | G127: =H127&I127&J127 -> 48303 | H127: 48 | I127: 30 | J127: 3 | K127: 50 | L127: (60-60x20, 60-29.7x10, 29.7-29.7x20)
A128: 132 | B128: BL03GCR1-06003050 | C128: BLUESTONE | D128: 03 | E128: Đá cây | F128: BLUESTONE, Đá cây-Giả cổ rung mặt và cạnh KT 60x30x5 SL:40 v/k | G128: =H128&I128&J128 -> 60305 | H128: 60 | I128: 30 | J128: 5 | K128: 40
A129: 133 | B129: BL03GCT1-10001050 | C129: BLUESTONE | D129: 03 | E129: Đá cây | F129: BLUESTONE, Đá cây-Giả cổ tay KT 100x15x5 SL:48 v/k | G129: =H129&I129&J129 -> 100155 | H129: 100 | I129: 15 | J129: 5 | K129: 48
A130: 134 | B130: BL03GCT1-10002050 | C130: BLUESTONE | D130: 03 | E130: Đá cây | F130: BLUESTONE, Đá cây-Giả cổ tay KT 100x20x5 SL:36 v/k | G130: =H130&I130&J130 -> 100205 | H130: 100 | I130: 20 | J130: 5 | K130: 36
A131: 135 | B131: BL03GCT1-10002100 | C131: BLUESTONE | D131: 03 | E131: Đá cây | F131: BLUESTONE, Đá cây-Giả cổ tay KT 100x25x10 SL:16 v/k | G131: =H131&I131&J131 -> 1002510 | H131: 100 | I131: 25 | J131: 10 | K131: 16
A132: 136 | B132: BL03GCT1-10003050 | C132: BLUESTONE | D132: 03 | E132: Đá cây | F132: BLUESTONE, Đá cây-Giả cổ tay KT 100x30x5 SL:24 v/k | G132: =H132&I132&J132 -> 100305 | H132: 100 | I132: 30 | J132: 5 | K132: 24
A133: 137 | B133: BL03GCT1-10005050 | C133: BLUESTONE | D133: 03 | E133: Đá cây | F133: BLUESTONE, Đá cây-Giả cổ tay KT 100x35x5 SL:20 v/k | G133: =H133&I133&J133 -> 100355 | H133: 100 | I133: 35 | J133: 5 | K133: 20
A134: 138 | B134: BL03GCT1-12502100 | C134: BLUESTONE | D134: 03 | E134: Đá cây | F134: BLUESTONE, Đá cây-Giả cổ tay KT 125x25x10 SL:14 v/k | G134: =H134&I134&J134 -> 1252510 | H134: 125 | I134: 25 | J134: 10 | K134: 14
A135: 139 | B135: BL03GCT1-05002100 | C135: BLUESTONE | D135: 03 | E135: Đá cây | F135: BLUESTONE, Đá cây-Giả cổ tay KT 50x25x10 SL:32 v/k | G135: =H135&I135&J135 -> 502510 | H135: 50 | I135: 25 | J135: 10 | K135: 32
...

Sheet Gia công chính
A1: Mã Gia Công
A3: Ký hiệu | B3: Nhóm mã gia công chính | C3: Gia công khác
A4: CTA | B4: Chẻ tay tự nhiên | C4: Xẻ rãnh
A5: CUA | B5: Mặt cưa | C5: Cắt góc vuông
A6: CLO | B6: Cưa lột tay | C6: Bo góc tròn
A7: TDE | B7: Tẩy đẹp | C7: Cắt chữ L
A8: DOT | B8: Mặt đốt | C8: Bo tròn 1 Cạnh
A9: HON | B9: Mặt hon | C9: Cắt vòng cung
A10: BON | B10: Mặt bóng | C10: Cắt chữ U
A11: BAM | B11: Mặt băm | C11: Bo cạnh và cắt chữ L
A12: GCR | B12: Giả cổ rung | C12: Bo góc và cắt chữ L
A13: GCT | B13: Giả cổ tay | C13: Khoan lỗ
A14: MGI | B14: Mài giấy | C14: Hình trụ
A15: PCA | B15: Mặt phun cát | C15: Hình chóp
A16: MCA | B16: Mài cát
A17: QME | B17: Quay mẻ
A18: TLO | B18: Tách lồi

Sheet 140421
A1: LỆNH TRIỂN KHAI SẢN XUẤT
A3: CTY CP KHOÁNG SẢN VẬT LIỆU Á CỘNG | D3: Số lệnh: | K3: Ngày soạn lệnh: | N3: Lần soạn lệnh:
A4: 1A Tầng 4, Broadway B | D4: 140421 (21/N-X59821) | K4: 44305 | N4: 1
A5: 102 Nguyễn Lương Bằng, P.Tân Phú, Q.7 | D5: Cảng xuất hàng: | K5: Cảng dỡ hàng: | N5: Ghi chú trên chứng từ:
A6: Tp.HCM | D6: Cảng Qui Nhơn | K6: Yokohama
A7: Tel: 5 412 2189 / Fax: 5 413 6218 | D7: Chất lượng: | K7: Hãng tàu/FWD: | N7: Cước tàu:
D8: theo chuẩn chất lượng đi Nhật | N8: C&F Yokohama
A9: STT | B9: MÃ SẢN PHẨM | C9: TÊN HÀNG | D9: KÍCH CỠ (cm) | G9: SỐ LƯỢNG | M9: Qui cách đóng gói | N9: GHI CHÚ | O9: THỜI GIAN GIAO HÀNG
D10: Dài | E10: Rộng | F10: Cao | G10: Viên | H10: Đơn vị | I10: Kiện | J10: m3 | K10: Tons | L10: Cont
A11: 1 | C11: Đá cây bazan - 2 mặt đốt, cạnh sộ tay (tiêu chuẩn đi Nhật) | D11: 90 | E11: 10 | F11: 10 | G11: 80 | H11: pcs | I11: =G11/M11 -> 2 | J11: =D11*E11*F11*G11/1000000 -> 0.72 | K11: =J11*2.7 -> 1.944 | L11: =K11/27 -> 0.072 | M11: 40 | N11: Hàng tiêu chuẩn đi Nhật | O11: Giao hàng tháng 5/2021
A12: 2 | C12: Đá vành Bazan - Mặt đốt, xung quanh da đá tự nhiên, đáy cưa. Tương tự LSX 260318. Xem hình ảnh bên dưới | D12: Đường kính 30-40 | F12: 6 | G12: 128 | H12: pcs | I12: =G12/M12 -> 2 | J12: =35*35*F12*G12/1000000 -> 0.9408 | K12: =J12*2.7 -> 2.54016 | L12: =K12/27 -> 0.09408 | M12: 64
C13: Tổng | G13: =SUM(G11:G12) -> 208 | I13: =SUM(I11:I12) -> 4 | J13: =SUM(J11:J12) -> 1.6608 | K13: =SUM(K11:K12) -> 4.48416 | L13: =SUM(L11:L12) -> 0.16608
A14: 1 | B14: BX03DOT1-09001100 | C14: =VLOOKUP(B14,'Ma SP'!B2:F520,5,FALSE) -> BAZAN XÁM, Đá cây-2 Mặt đốt, Cạnh còn lại sộ tay KT 90x10x10 SL:40 v/k | D14: =VLOOKUP(B14,'Ma SP'!B2:L517,6,FALSE) -> 901010 | E14: =VLOOKUP(B14,'Ma SP'!B2:J517,7,FALSE) -> 90 | F14: =VLOOKUP(B14,'Ma SP'!B2:K517,8,FALSE) -> 10 | G14: 80 | H14: pcs | I14: =G14/M14 -> 2 | J14: =D14*E14*F14*G14/1000000 -> 64872.72 | K14: =J14*2.7 -> 175156.34 | L14: =K14/27 -> 6487.272 | M14: 40 | N14: Hàng tiêu chuẩn đi Nhật | O14: Giao hàng tháng 5/2021
A15: 2 | B15: BX01DOT1-04003060 | C15: =VLOOKUP(B15,'Ma SP'!B3:F521,5,FALSE) -> BAZAN XÁM, Đá vành-Mặt đốt, cạnh da đá, đáy cưa KT 30-40x30-40x6 SL: 64 v/k | D15: =VLOOKUP(B15,'Ma SP'!B3:L518,6,FALSE) -> 40306 | E15: =VLOOKUP(B15,'Ma SP'!B3:J518,7,FALSE) -> 40 | F15: =VLOOKUP(B15,'Ma SP'!B3:K518,8,FALSE) -> 30 | G15: 128 | H15: pcs | I15: =G15/M15 -> 2 | J15: =35*35*F15*G15/1000000 -> 4.704 | K15: =J15*2.7 -> 12.7008 | L15: =K15/27 -> 0.4704 | M15: 64
C16: Tổng | G16: =SUM(G14:G15) -> 208 | I16: =SUM(I14:I15) -> 4 | J16: =SUM(J14:J15) -> 64877.424 | K16: =SUM(K14:K15) -> 175169.04 | L16: =SUM(L14:L15) -> 6487.7424
A18: GHI CHÚ KHÁC: | M18: Người soạn lệnh
M20: Bích Nguyễn

Sheet 130421
A1: LỆNH TRIỂN KHAI SẢN XUẤT
A3: CTY CP KHOÁNG SẢN VẬT LIỆU Á CỘNG | D3: Số lệnh: | K3: Ngày soạn lệnh: | M3: Lần soạn lệnh:
A4: 1A Tầng 4, Broadway A | D4: 130421 (01/A-X23.2/21) | K4: 44300 | M4: 1
A5: 100 Nguyễn Lương Bằng, P.Tân Phú, Q.7 | D5: Cảng xuất hàng: | K5: Cảng dỡ hàng: | M5: Ghi chú trên chứng từ:
A6: Tp.HCM | D6: Cảng Quy Nhơn | K6: ROTTERDAM
A7: Tel: 5 412 2189 / Fax: 5 413 6218 | D7: Chất lượng: | K7: Hãng tàu/FWD: | M7: Cước tàu:
D8: Theo chuẩn chất lượng đi Châu Âu | M8: FOB
A9: STT | B9: MÃ SẢN PHẨM | C9: TÊN HÀNG | D9: KÍCH CỠ (CM) | L9: Qui cách đóng gói | M9: GHI CHÚ | N9: THỜI GIAN GIAO HÀNG
D10: Dài | E10: Rộng | F10: Dày | G10: Viên | H10: M2 | I10: Kiện | J10: m3 | K10: CONTAINER
A11: 1 | C11: Đá bazan Cubic Chẻ tay tự nhiên | D11: 10 | E11: 10 | F11: 9 | G11: 5600 | H11: =G11*D11*E11/10000 -> 56 | I11: =G11/L11 -> 8 | J11: =G11*F11*E11*D11/1000000 -> 5.04 | K11: =J11*2.65*0.875/27 -> 0.43283333 | L11: 700 | N11: Giao hàng Tháng 5/2021
A12: 2 | D12: 20 | E12: 10 | F12: 9 | G12: 2100 | I12: =G12/L12 -> 7 | J12: =G12*F12*E12*D12/1000000 -> 3.78 | K12: =J12*2.65*0.875/27 -> 0.324625 | L12: 300
A13: 3 | C13: Đá lát bazan Chẻ tay tự nhiên. Dung sai của độ dày ± 3mm | D13: 30 | E13: 20 | F13: 6 | G13: 720 | I13: =G13/L13 -> 6 | J13: =G13*F13*E13*D13/1000000 -> 2.592 | K13: =J13*2.65/27 -> 0.2544 | L13: 120
C14: Tổng cộng: | I14: =SUM(I11:I13) -> 21 | J14: =SUM(J11:J13) -> 11.412 | K14: =SUM(K11:K13) -> 1.0118583
A15: 1 | B15: BX01CTA1-01001090 | C15: =VLOOKUP(B15,'Ma SP'!B3:F521,5,FALSE) -> BAZAN XÁM, Cubic-Chẻ tay tự nhiên KT 10x10x9 SL:700 v/k | D15: =VLOOKUP(B15,'Ma SP'!B3:L518,6,FALSE) -> 10109 | E15: =VLOOKUP(B15,'Ma SP'!B3:J518,7,FALSE) -> 10 | F15: =VLOOKUP(B15,'Ma SP'!B3:K518,8,FALSE) -> 10 | G15: 5600 | H15: =G15*D15*E15/10000 -> 56610.4 | I15: =G15/L15 -> 8 | J15: =G15*F15*E15*D15/1000000 -> 5661.04 | K15: =J15*2.65*0.875/27 -> 486.16802 | L15: 700 | N15: Giao hàng Tháng 5/2021
A16: 2 | B16: BX01CTA1-02001090 | C16: =VLOOKUP(B16,'Ma SP'!B3:F522,5,FALSE) -> BAZAN XÁM, Cubic-Chẻ tay tự nhiên KT 20x10x9 SL:300 v/k | D16: =VLOOKUP(B16,'Ma SP'!B3:L519,6,FALSE) -> 20109 | E16: =VLOOKUP(B16,'Ma SP'!B3:J519,7,FALSE) -> 20 | F16: =VLOOKUP(B16,'Ma SP'!B3:K519,8,FALSE) -> 10 | G16: 2100 | I16: =G16/L16 -> 7 | J16: =G16*F16*E16*D16/1000000 -> 8445.78 | K16: =J16*2.65*0.875/27 -> 725.32046 | L16: 300
A17: 3 | B17: BX01CTA1-03002060 | C17: =VLOOKUP(B17,'Ma SP'!B3:F523,5,FALSE) -> BAZAN XÁM, Đá Lát-Chẻ tay tự nhiên KT 30x20x6 SL: 120 v/k | D17: =VLOOKUP(B17,'Ma SP'!B3:L520,6,FALSE) -> 30206 | E17: =VLOOKUP(B17,'Ma SP'!B3:J520,7,FALSE) -> 30 | F17: =VLOOKUP(B17,'Ma SP'!B3:K520,8,FALSE) -> 20 | G17: 720 | I17: =G17/L17 -> 6 | J17: =G17*F17*E17*D17/1000000 -> 13048.992 | K17: =J17*2.65/27 -> 1280.7344 | L17: 120 | M17: Dung sai của độ dày ± 3mm
C18: Tổng cộng: | I18: =SUM(I15:I17) -> 21 | J18: =SUM(J15:J17) -> 27155.812 | K18: =SUM(K15:K17) -> 2492.2229
A20: GHI CHÚ KHÁC: | M20: Người soạn lệnh
M23: Bích Nguyễn

Sheet 110421
A1: LỆNH TRIỂN KHAI SẢN XUẤT
A3: CTY CP KHOÁNG SẢN VẬT LIỆU Á CỘNG | D3: Số lệnh: | L3: Ngày soạn lệnh: | O3: Lần soạn lệnh:
A4: 1A Tầng 4, Broadway B | D4: 110421 (03/A-X87/21) | L4: 44298 | O4: 1
A5: 102 Nguyễn Lương Bằng, P.Tân Phú, Q.7 | D5: Cảng xuất hàng: | L5: Cảng dỡ hàng: | O5: Ghi chú trên chứng từ:
A6: Tp.HCM | D6: Qui Nhon port | L6: OAKLAND, CA, USA
A7: Tel: 5 412 2189 / Fax: 5 413 6218 | D7: Chất lượng: | L7: Hãng tàu/FWD: | O7: Cước tàu:
D8: Theo tiêu chuẩn xuất khẩu trong kiện gỗ | O8: FOB
A9: STT | B9: MÁ SP | C9: TÊN HÀNG | G9: SỐ LƯỢNG | N9: Ghi chú | O9: GHI CHÚ | P9: THỜI GIAN GIAO HÀNG
D10: Dài (cm) | E10: Rộng (cm) | F10: Dày (cm) | G10: Số Viên | H10: Số Kiện | I10: m2 | J10: m3 | K10: Ton | L10: Cont | M10: Packing
P11: Giao hàng đầu tháng 6/2021
A12: 1 | C12: Đá lát Bazan xám Mặt đốt, cạnh cưa, vạt mép 3mm 24" x 16" x 1-3/16" | D12: 61 | E12: 40.6 | F12: 3 | G12: 510 | H12: =G12/M12 -> 15 | I12: =D12*E12*G12/10000 -> 126.3066 | J12: =D12*E12*F12*G12/1000000 -> 3.789198 | K12: =J12*2.7 -> 10.230835 | L12: =K12/20 -> 0.51154173 | M12: 34 | N12: Nguyên liệu mỏ số 6 - Gia Lai
A13: 2 | C13: Đá lát Bazan xám Cưa và đốt tất cả các mặt, vạt mép 3mm 24" x 16" x 2" | D13: 61 | E13: 40.6 | F13: 5 | G13: 140 | H13: =G13/M13 -> 7 | I13: =D13*E13*G13/10000 -> 34.6724 | J13: =D13*E13*F13*G13/1000000 -> 1.73362 | K13: =J13*2.7 -> 4.680774 | L13: =K13/20 -> 0.2340387 | M13: 20
A14: 3 | C14: Đá slab Bazan xám Mặt đốt 80" x 26" x 1-3/16" | D14: 200-220 | E14: 64-68 | F14: 3 | G14: 11 | H14: =G14/M14 -> 1 | I14: =G14*66*210/10000 -> 15.246 | J14: =I14*F14/100 -> 0.45738 | K14: =J14*2.7 -> 1.234926 | L14: =K14/20 -> 0.0617463 | M14: 11
A15: 4 | C15: Đá slab Bazan đen Mặt honed 80" x 26" x 3/4" | D15: 200-220 | E15: 64-68 | F15: 2 | G15: 20 | H15: =G15/M15 -> 1 | I15: =G15*66*210/10000 -> 27.72 | J15: =I15*F15/100 -> 0.5544 | K15: =J15*2.7 -> 1.49688 | L15: =K15/20 -> 0.074844 | M15: 20 | N15: Nguyên liệu mỏ số 5
G16: =SUM(G12:G15) -> 681 | H16: =SUM(H12:H15) -> 24 | I16: =SUM(I12:I15) -> 203.945 | J16: =SUM(J12:J15) -> 6.534598 | K16: =SUM(K12:K15) -> 17.643415 | L16: =SUM(L12:L15) -> 0.88217073
A17: 1 | B17: BX01DOT1-06104030 | C17: =VLOOKUP(B17,'Ma SP'!B3:F523,5,FALSE) -> BAZAN XÁM, Đá lát-Mặt đốt, cạnh cưa, vạt mép 3mm KT 61x40.6x3 SL:34 v/k | D17: =VLOOKUP(B17,'Ma SP'!B3:L520,6,FALSE) -> 6140.63 | E17: =VLOOKUP(B17,'Ma SP'!B3:J520,7,FALSE) -> 61 | F17: =VLOOKUP(B17,'Ma SP'!B3:K520,8,FALSE) -> 40.6 | G17: 510 | H17: =G17/M17 -> 15 | I17: =D17*E17*G17/10000 -> 19103.5 | J17: =D17*E17*F17*G17/1000000 -> 7756.021 | K17: =J17*2.7 -> 20941.257 | L17: =K17/20 -> 1047.0628 | M17: 34 | N17: Nguyên liệu mỏ số 6 - Gia Lai | P17: Giao hàng đầu tháng 6/2021
A18: 2 | B18: BX03DOT1-06104050 | C18: =VLOOKUP(B18,'Ma SP'!B4:F524,5,FALSE) -> BAZAN XÁM, Đá cây-6 mặt đốt chải, vạt mép 3mm KT 61x40.6x5 SL:20 v/k | D18: =VLOOKUP(B18,'Ma SP'!B4:L521,6,FALSE) -> 6140.65 | E18: =VLOOKUP(B18,'Ma SP'!B4:J521,7,FALSE) -> 61 | F18: =VLOOKUP(B18,'Ma SP'!B4:K521,8,FALSE) -> 40.6 | G18: 140 | H18: =G18/M18 -> 7 | I18: =D18*E18*G18/10000 -> 5244.1151 | J18: =D18*E18*F18*G18/1000000 -> 2129.1107 | K18: =J18*2.7 -> 5748.599 | L18: =K18/20 -> 287.42995 | M18: 20
A19: 3 | B19: BX08DOT1-22006030 | C19: =VLOOKUP(B19,'Ma SP'!B5:F525,5,FALSE) -> BAZAN XÁM, Đá Tấm-Mặt đốt KT 200-220x64-68x3 SL: 11 v/k | D19: =VLOOKUP(B19,'Ma SP'!B5:L522,6,FALSE) -> 220683 | E19: =VLOOKUP(B19,'Ma SP'!B5:J522,7,FALSE) -> 220 | F19: =VLOOKUP(B19,'Ma SP'!B5:K522,8,FALSE) -> 68 | G19: 11 | H19: =G19/M19 -> 1 | I19: =G19*66*210/10000 -> 15.246 | J19: =I19*F19/100 -> 10.36728 | K19: =J19*2.7 -> 27.991656 | L19: =K19/20 -> 1.3995828 | M19: 11
A20: 4 | B20: BD08DOT1-22006020 | C20: =VLOOKUP(B20,'Ma SP'!B6:F526,5,FALSE) -> BAZAN ĐEN, Đá Tấm-Mặt đốt KT 200-220x64-68x2 SL: 20 v/k | D20: =VLOOKUP(B20,'Ma SP'!B6:L523,6,FALSE) -> 0 | E20: =VLOOKUP(B20,'Ma SP'!B6:J523,7,FALSE) -> 220 | F20: =VLOOKUP(B20,'Ma SP'!B6:K523,8,FALSE) -> 68 | G20: 20 | H20: =G20/M20 -> 1 | I20: =G20*66*210/10000 -> 27.72 | J20: =I20*F20/100 -> 18.8496 | K20: =J20*2.7 -> 50.89392 | L20: =K20/20 -> 2.544696 | M20: 20 | N20: Nguyên liệu mỏ số 5
G21: =SUM(G17:G20) -> 681 | H21: =SUM(H17:H20) -> 24 | I21: =SUM(I17:I20) -> 24390.581 | J21: =SUM(J17:J20) -> 9914.3486 | K21: =SUM(K17:K20) -> 26768.741 | L21: =SUM(L17:L20) -> 1338.4371
A23: GHI CHÚ KHÁC: | N23: Người soạn lệnh
N27: Tốt Huê

Sheet Mã kích thước
A1: Mã | B1: Mô tả | C1: Mã KT | D1: D | E1: R | F1: C
A2: 001 | B2: =D2&"x"&E2&"x"&F2 -> 5x5x5 | C2: 001 | D2: 5 | E2: 5 | F2: 5
A3: 002 | B3: =D3&"x"&E3&"x"&F3 -> 9x9x3 | C3: 002 | D3: 9 | E3: 9 | F3: 3
A4: 003 | B4: =D4&"x"&E4&"x"&F4 -> 9x9x4.5 | C4: 003 | D4: 9 | E4: 9 | F4: 4.5
A5: 004 | B5: =D5&"x"&E5&"x"&F5 -> 9x9x5 | C5: 004 | D5: 9 | E5: 9 | F5: 5
A6: 005 | B6: =D6&"x"&E6&"x"&F6 -> 9x9x7 | C6: 005 | D6: 9 | E6: 9 | F6: 7
A7: 006 | B7: =D7&"x"&E7&"x"&F7 -> 9x9x8 | C7: 006 | D7: 9 | E7: 9 | F7: 8
A8: 007 | B8: =D8&"x"&E8&"x"&F8 -> 9x9x9 | C8: 007 | D8: 9 | E8: 9 | F8: 9
A9: 008 | B9: =D9&"x"&E9&"x"&F9 -> 10x10x3 | C9: 008 | D9: 10 | E9: 10 | F9: 3
A10: 009 | B10: =D10&"x"&E10&"x"&F10 -> 10x10x5 | C10: 009 | D10: 10 | E10: 10 | F10: 5
A11: 010 | B11: =D11&"x"&E11&"x"&F11 -> 10x10x6 | C11: 010 | D11: 10 | E11: 10 | F11: 6
A12: 011 | B12: =D12&"x"&E12&"x"&F12 -> 10x10x8 | C12: 011 | D12: 10 | E12: 10 | F12: 8
A13: 012 | B13: =D13&"x"&E13&"x"&F13 -> 10x10x8.5 | C13: 012 | D13: 10 | E13: 10 | F13: 8.5
... A226: 225 | B226: =D226&"x"&E226&"x"&F226 -> 104.1x68.6x4 | C226: 225 | D226: 104.1 | E226: 68.6 | F226: 4
A227: 226 | B227: =D227&"x"&E227&"x"&F227 -> 106.6x43x5/3 | C227: 226 | D227: 106.6 | E227: 43 | F227: 5/3
A228: 227 | B228: =D228&"x"&E228&"x"&F228 -> 106.7x45.7x2 | C228: 227 | D228: 106.7 | E228: 45.7 | F228: 2
A229: 228 | B229: =D229&"x"&E229&"x"&F229 -> 106.7x61x5 | C229: 228 | D229: 106.7 | E229: 61 | F229: 5
A230: 229 | B230: =D230&"x"&E230&"x"&F230 -> 106.7x68.6x4 | C230: 229 | D230: 106.7 | E230: 68.6 | F230: 4
A231: 230 | B231: =D231&"x"&E231&"x"&F231 -> 109.28x28x5/3 | C231: 230 | D231: 109.28 | E231: 28 | F231: 5/3
A232: 231 | B232: =D232&"x"&E232&"x"&F232 -> 113.7x15.2x2 | C232: 231 | D232: 113.7 | E232: 15.2 | F232: 2
A233: 232 | B233: =D233&"x"&E233&"x"&F233 -> 113.7x29.8x2 | C233: 232 | D233: 113.7 | E233: 29.8 | F233: 2
A234: 233 | B234: =D234&"x"&E234&"x"&F234 -> 116.2x15.2x2 | C234: 233 | D234: 116.2 | E234: 15.2 | F234: 2
A235: 234 | B235: =D235&"x"&E235&"x"&F235 -> 116.2x29.8x2 | C235: 234 | D235: 116.2 | E235: 29.8 | F235: 2
A236: 235 | B236: =D236&"x"&E236&"x"&F236 -> 120x12x12 | C236: 235 | D236: 120 | E236: 12 | F236: 12
A237: 236 | B237: =D237&"x"&E237&"x"&F237 -> 120x14.5x2 | C237: 236 | D237: 120 | E237: 14.5 | F237: 2
A238: 237 | B238: =D238&"x"&E238&"x"&F238 -> 120x14.5x3 | C238: 237 | D238: 120 | E238: 14.5 | F238: 3
A239: 238 | B239: =D239&"x"&E239&"x"&F239 -> 120x25x10 | C239: 238 | D239: 120 | E239: 25 | F239: 10
A240: 239 | B240: =D240&"x"&E240&"x"&F240 -> 120x30x3 | C240: 239 | D240: 120 | E240: 30 | F240: 3
A241: 240 | B241: =D241&"x"&E241&"x"&F241 -> 120x35x3 | C241: 240 | D241: 120 | E241: 35 | F241: 3
A242: 241 | B242: =D242&"x"&E242&"x"&F242 -> 120x35x15 | C242: 241 | D242: 120 | E242: 35 | F242: 15
A243: 242 | B243: =D243&"x"&E243&"x"&F243 -> 121.4x20x10.2 | C243: 242 | D243: 121.4 | E243: 20 | F243: 10.2
... A305: 304 | B305: =D305&"x"&E305&"x"&F305 -> 250x25x10 | C305: 304 | D305: 250 | E305: 25 | F305: 10
A306: 305 | B306: =D306&"x"&E306&"x"&F306 -> 14-18-22x12x6 | C306: 305 | D306: 14-18-22 | E306: 12 | F306: 6
A307: 306 | B307: =D307&"x"&E307&"x"&F307 -> 150-220x60x3 | C307: 306 | D307: 150-220 | E307: 60 | F307: 3
A308: 307 | B308: =D308&"x"&E308&"x"&F308 -> 150-220x60x4 | C308: 307 | D308: 150-220 | E308: 60 | F308: 4
A309: 308 | B309: =D309&"x"&E309&"x"&F309 -> 150-220x80x3 | C309: 308 | D309: 150-220 | E309: 80 | F309: 3
A310: 309 | B310: =D310&"x"&E310&"x"&F310 -> 150-220x80x4 | C310: 309 | D310: 150-220 | E310: 80 | F310: 4
A311: 310 | B311: =D311&"x"&E311&"x"&F311 -> 180-220x60x4 | C311: 310 | D311: 180-220 | E311: 60 | F311: 4
A312: 311 | B312: =D312&"x"&E312&"x"&F312 -> 19.5-60x19.5-40x2 | C312: 311 | D312: 19.5-60 | E312: 19.5-40 | F312: 2
A313: 312 | B313: =D313&"x"&E313&"x"&F313 -> 19.5-60x19.5-40x2.5 | C313: 312 | D313: 19.5-60 | E313: 19.5-40 | F313: 2.5
...

Sheet DANH MUC SP
A1: Mã sản phẩm | B1: Mô tả chung | C1: Loại đá | D1: Loại sản phẩm | E1: Gia công | F1: D | G1: R | H1: C | I1: Đóng gói | J1: Ghi chú
A2: BD061100216-10V | B2: Đá bậc thang Bazan đen, 5 mặt đốt xịt nước, vạt mép 3mm, KT 100x35x15, Đóng gói 10V | C2: Bazan đen | D2: Đá bậc thang | E2: 5 mặt đốt xịt nước, vạt mép 3mm | F2: 100 | G2: 35 | H2: 15 | I2: 10
A3: BD061100216-5V | B3: Đá bậc thang Bazan đen, 5 mặt đốt xịt nước, vạt mép 3mm, KT 100x35x15, Đóng gói 5V | C3: Bazan đen | D3: Đá bậc thang | E3: 5 mặt đốt xịt nước, vạt mép 3mm | F3: 100 | G3: 35 | H3: 15 | I3: 5
A4: BD061100251 | B4: Đá bậc thang Bazan đen, 5 mặt đốt xịt nước, vạt mép 3mm, KT 125x35x15, Đóng gói 8V | C4: Bazan đen | D4: Đá bậc thang | E4: 5 mặt đốt xịt nước, vạt mép 3mm | F4: 125 | G4: 35 | H4: 15 | I4: 8
A5: BD061100272 | B5: Đá bậc thang Bazan đen, 5 mặt đốt xịt nước, vạt mép 3mm, KT 150x35x15, Đóng gói 6V | C5: Bazan đen | D5: Đá bậc thang | E5: 5 mặt đốt xịt nước, vạt mép 3mm | F5: 150 | G5: 35 | H5: 15 | I5: 6
A6: BD061100152 | B6: Đá bậc thang Bazan đen, 5 mặt đốt xịt nước, vạt mép 3mm, KT 75x35x15, Đóng gói 10V | C6: Bazan đen | D6: Đá bậc thang | E6: 5 mặt đốt xịt nước, vạt mép 3mm | F6: 75 | G6: 35 | H6: 15 | I6: 10
A7: BD061306184 | B7: Đá bậc thang Bazan đen, 6 mặt đốt xịt nước, vạt mép cạnh dài 5mm, vạt mép cạnh ngắn 3mm, KT 100x10x8, Đóng gói 42V | C7: Bazan đen | D7: Đá bậc thang | E7: 6 mặt đốt xịt nước, vạt mép cạnh dài 5mm, vạt mép cạnh ngắn 3mm | F7: 100 | G7: 10 | H7: 8 | I7: 42
A8: BD061300185 | B8: Đá bậc thang Bazan đen, 6 mặt đốt xịt nước, vạt mép 3mm, KT 100x12x12, Đóng gói 32V | C8: Bazan đen | D8: Đá bậc thang | E8: 6 mặt đốt xịt nước, vạt mép 3mm | F8: 100 | G8: 12 | H8: 12 | I8: 32
A9: BD061306187 | B9: Đá bậc thang Bazan đen, 6 mặt đốt xịt nước, vạt mép cạnh dài 5mm, vạt mép cạnh ngắn 3mm, KT 100x15x8, Đóng gói 12V | C9: Bazan đen | D9: Đá bậc thang | E9: 6 mặt đốt xịt nước, vạt mép cạnh dài 5mm, vạt mép cạnh ngắn 3mm | F9: 100 | G9: 15 | H9: 8 | I9: 12
A10: BD061306193 | B10: Đá bậc thang Bazan đen, 6 mặt đốt xịt nước, vạt mép cạnh dài 5mm, vạt mép cạnh ngắn 3mm, KT 100x20x8, Đóng gói 20V | C10: Bazan đen | D10: Đá bậc thang | E10: 6 mặt đốt xịt nước, vạt mép cạnh dài 5mm, vạt mép cạnh ngắn 3mm | F10: 100 | G10: 20 | H10: 8 | I10: 20
A11: BD061306216-10V | B11: Đá bậc thang Bazan đen, 6 mặt đốt xịt nước, vạt mép cạnh dài 5mm, vạt mép cạnh ngắn 3mm, KT 100x35x15, Đóng gói 10V | C11: Bazan đen | D11: Đá bậc thang | E11: 6 mặt đốt xịt nước, vạt mép cạnh dài 5mm, vạt mép cạnh ngắn 3mm | F11: 100 | G11: 35 | H11: 15 | I11: 10
A12: BD061306216-5V | B12: Đá bậc thang Bazan đen, 6 mặt đốt xịt nước, vạt mép cạnh dài 5mm, vạt mép cạnh ngắn 3mm, KT 100x35x15, Đóng gói 5V | C12: Bazan đen | D12: Đá bậc thang | E12: 6 mặt đốt xịt nước, vạt mép cạnh dài 5mm, vạt mép cạnh ngắn 3mm | F12: 100 | G12: 35 | H12: 15 | I12: 5
A13: BD061306216-8V | B13: Đá bậc thang Bazan đen, 6 mặt đốt xịt nước, vạt mép cạnh dài 5mm, vạt mép cạnh ngắn 3mm, KT 100x35x15, Đóng gói 8V | C13: Bazan đen | D13: Đá bậc thang | E13: 6 mặt đốt xịt nước, vạt mép cạnh dài 5mm, vạt mép cạnh ngắn 3mm | F13: 100 | G13: 35 | H13: 15 | I13: 8
... A82: BD021300161 | B82: Đá lát Bazan đen, 6 mặt đốt xịt nước, vạt mép 3mm, KT 80x40x4, Đóng gói 20V | C82: Bazan đen | D82: Đá lát | E82: 6 mặt đốt xịt nước, vạt mép 3mm | F82: 80 | G82: 40 | H82: 4 | I82: 20
A83: BD020805305 | B83: Đá lát Bazan đen, Mặt đốt xịt nước, cạnh cưa, vạt mép 3mm, KT 14-18-22x12x6, Đóng gói 192V | C83: Bazan đen | D83: Đá lát | E83: Mặt đốt xịt nước, cạnh cưa, vạt mép 3mm | F83: 14-18-22 | G83: 12 | H83: 6 | I83: 192
A84: BD020802021 | B84: Đá lát Bazan đen, Mặt đốt xịt nước, cạnh cưa , KT 15x15x1.2, Đóng gói 250V | C84: Bazan đen | D84: Đá lát | E84: Mặt đốt xịt nước, cạnh cưa | F84: 15 | G84: 15 | H84: 1.2 | I84: 250
A85: BD020805035 | B85: Đá lát Bazan đen, Mặt đốt xịt nước, cạnh cưa, vạt mép 3mm, KT 20x10x3, Đóng gói 660V | C85: Bazan đen | D85: Đá lát | E85: Mặt đốt xịt nước, cạnh cưa, vạt mép 3mm | F85: 20 | G85: 10 | H85: 3 | I85: 660
A86: BD020805061 | B86: Đá lát Bazan đen, Mặt đốt xịt nước, cạnh cưa, vạt mép 3mm, KT 35x15x6, Đóng gói 128V | C86: Bazan đen | D86: Đá lát | E86: Mặt đốt xịt nước, cạnh cưa, vạt mép 3mm | F86: 35 | G86: 15 | H86: 6 | I86: 128
A87: BD020805111 | B87: Đá lát Bazan đen, Mặt đốt xịt nước, cạnh cưa, vạt mép 3mm, KT 60x30x3, Đóng gói 68V | C87: Bazan đen | D87: Đá lát | E87: Mặt đốt xịt nước, cạnh cưa, vạt mép 3mm | F87: 60 | G87: 30 | H87: 3 | I87: 68
A88: BD020805119 | B88: Đá lát Bazan đen, Mặt đốt xịt nước, cạnh cưa, vạt mép 3mm, KT 60x40x3, Đóng gói 34V | C88: Bazan đen | D88: Đá lát | E88: Mặt đốt xịt nước, cạnh cưa, vạt mép 3mm | F88: 60 | G88: 40 | H88: 3 | I88: 34
A89: BD020803123 | B89: Đá lát Bazan đen, Mặt đốt xịt nước, cạnh cưa, vạt mép 1mm, KT 60x60x3, Đóng gói 34V | C89: Bazan đen | D89: Đá lát | E89: Mặt đốt xịt nước, cạnh cưa, vạt mép 1mm | F89: 60 | G89: 60 | H89: 3 | I89: 34
A90: BD020805158 | B90: Đá lát Bazan đen, Mặt đốt xịt nước, cạnh cưa, vạt mép 3mm, KT 80x30x3, Đóng gói 34V | C90: Bazan đen | D90: Đá lát | E90: Mặt đốt xịt nước, cạnh cưa, vạt mép 3mm | F90: 80 | G90: 30 | H90: 3 | I90: 34
A91: BD020805160 | B91: Đá lát Bazan đen, Mặt đốt xịt nước, cạnh cưa, vạt mép 3mm, KT 80x40x3, Đóng gói 34V | C91: Bazan đen | D91: Đá lát | E91: Mặt đốt xịt nước, cạnh cưa, vạt mép 3mm | F91: 80 | G91: 40 | H91: 3 | I91: 34
A92: BD020805170 | B92: Đá lát Bazan đen, Mặt đốt xịt nước, cạnh cưa, vạt mép 3mm, KT 90x45x3, Đóng gói 30V | C92: Bazan đen | D92: Đá lát | E92: Mặt đốt xịt nước, cạnh cưa, vạt mép 3mm | F92: 90 | G92: 45 | H92: 3 | I92: 30
A93: BD020805174 | B93: Đá lát Bazan đen, Mặt đốt xịt nước, cạnh cưa, vạt mép 3mm, KT 90x60x3, Đóng gói 20V | C93: Bazan đen | D93: Đá lát | E93: Mặt đốt xịt nước, cạnh cưa, vạt mép 3mm | F93: 90 | G93: 60 | H93: 3 | I93: 20
A94: BD020803174 | B94: Đá lát Bazan đen, Mặt đốt xịt nước, cạnh cưa, vạt mép 1mm, KT 90x60x3, Đóng gói 25V | C94: Bazan đen | D94: Đá lát | E94: Mặt đốt xịt nước, cạnh cưa, vạt mép 1mm | F94: 90 | G94: 60 | H94: 3 | I94: 25
A95: BD040800306 | B95: Đá tấm Bazan đen, Đốt xịt nước, KT 150-220x60x3, Đóng gói 20V | C95: Bazan đen | D95: Đá tấm | E95: Đốt xịt nước | F95: 150-220 | G95: 60 | H95: 3 | I95: 20
A96: BD040800307 | B96: Đá tấm Bazan đen, Đốt xịt nước, KT 150-220x60x4, Đóng gói 12V | C96: Bazan đen | D96: Đá tấm | E96: Đốt xịt nước | F96: 150-220 | G96: 60 | H96: 4 | I96: 12
A97: BD040800308 | B97: Đá tấm Bazan đen, Đốt xịt nước, KT 150-220x80x3, Đóng gói 10V | C97: Bazan đen | D97: Đá tấm | E97: Đốt xịt nước | F97: 150-220 | G97: 80 | H97: 3 | I97: 10
A98: BD040800309 | B98: Đá tấm Bazan đen, Đốt xịt nước, KT 150-220x80x4, Đóng gói 8V | C98: Bazan đen | D98: Đá tấm | E98: Đốt xịt nước | F98: 150-220 | G98: 80 | H98: 4 | I98: 8
A99: BD040800310 | B99: Đá tấm Bazan đen, Đốt xịt nước, KT 180-220x60x4, Đóng gói 12V | C99: Bazan đen | D99: Đá tấm | E99: Đốt xịt nước | F99: 180-220 | G99: 60 | H99: 4 | I99: 12
A100: BD040830207 | B100: Đá tấm Bazan đen, Mặt đốt xịt nước, 2 cạnh dài hon, 2 mép dài trên bo tròn R=0.5cm và hon cùng màu cạnh, 2 mép dài dưới vạt 3mm, KT 100x30x6, Đóng gói 20V | C100: Bazan đen | D100: Đá tấm | E100: Mặt đốt xịt nước, 2 cạnh dài hon, 2 mép dài trên bo tròn R=0.5cm và hon cùng màu cạnh, 2 mép dài dưới vạt 3mm | F100: 100 | G100: 30 | H100: 6 | I100: 20
A101: BD081200150 | B101: Đá nắp tường rào Bazan đen, 5 mặt đốt xịt nước, 2 rãnh thoát nước dọc 2 cạnh dài 0.5x0.5cm cách mép 1.5cm, vạt mép 3mm, đáy cưa, KT 75x30x4, Đóng gói 30V | C101: Bazan đen | D101: Đá nắp tường rào | E101: 5 mặt đốt xịt nước, 2 rãnh thoát nước dọc 2 cạnh dài 0.5x0.5cm cách mép 1.5cm, vạt mép 3mm, đáy cưa | F101: 75 | G101: 30 | H101: 4 | I101: 30
A102: BD081200151 | B102: Đá nắp tường rào Bazan đen, 5 mặt đốt xịt nước, 2 rãnh thoát nước dọc 2 cạnh dài 0.5x0.5cm cách mép 1.5cm, vạt mép 3mm, đáy cưa, KT 75x35x4, Đóng gói 30V | C102: Bazan đen | D102: Đá nắp tường rào | E102: 5 mặt đốt xịt nước, 2 rãnh thoát nước dọc 2 cạnh dài 0.5x0.5cm cách mép 1.5cm, vạt mép 3mm, đáy cưa | F102: 75 | G102: 35 | H102: 4 | I102: 30
A103: BD081200153 | B103: Đá nắp tường rào Bazan đen, 5 mặt đốt xịt nước, 2 rãnh thoát nước dọc 2 cạnh dài 0.5x0.5cm cách mép 1.5cm, vạt mép 3mm, đáy cưa, KT 75x40x4, Đóng gói 30V | C103: Bazan đen | D103: Đá nắp tường rào | E103: 5 mặt đốt xịt nước, 2 rãnh thoát nước dọc 2 cạnh dài 0.5x0.5cm cách mép 1.5cm, vạt mép 3mm, đáy cưa | F103: 75 | G103: 40 | H103: 4 | I103: 30
A104: BD080833202 | B104: Đá nắp tường rào Bazan đen, Mặt đốt xịt nước, 2 cạnh dài chẻ tay tự nhiên, 2 rãnh thoát nước dọc 2 cạnh dài 0.8x0.8cm cách mép 2cm, KT 100x26x5, Đóng gói 20V | C104: Bazan đen | D104: Đá nắp tường rào | E104: Mặt đốt xịt nước, 2 cạnh dài chẻ tay tự nhiên, 2 rãnh thoát nước dọc 2 cạnh dài 0.8x0.8cm cách mép 2cm | F104: 100 | G104: 26 | H104: 5 | I104: 20
A105: BD080833205 | B105: Đá nắp tường rào Bazan đen, Mặt đốt xịt nước, 2 cạnh dài chẻ tay tự nhiên, 2 rãnh thoát nước dọc 2 cạnh dài 0.5x0.5cm cách mép 1.5cm, KT 100x30x4, Đóng gói 25V | C105: Bazan đen | D105: Đá nắp tường rào | E105: Mặt đốt xịt nước, 2 cạnh dài chẻ tay tự nhiên, 2 rãnh thoát nước dọc 2 cạnh dài 0.5x0.5cm cách mép 1.5cm | F105: 100 | G105: 30 | H105: 4 | I105: 25
A106: BD080831195 | B106: Đá nắp tường rào Bazan đen, Mặt đốt xịt nước, 2 cạnh dài hon, 2 rãnh thoát nước dọc 2 cạnh dài 0.5x0.5cm cách mép 1.5cm, vạt 4 mép cạnh dài 3mm, KT 100x25x4, Đóng gói 25V | C106: Bazan đen | D106: Đá nắp tường rào | E106: Mặt đốt xịt nước, 2 cạnh dài hon, 2 rãnh thoát nước dọc 2 cạnh dài 0.5x0.5cm cách mép 1.5cm, vạt 4 mép cạnh dài 3mm | F106: 100 | G106: 25 | H106: 4 | I106: 25
A107: BD080831204 | B107: Đá nắp tường rào Bazan đen, Mặt đốt xịt nước, 2 cạnh dài hon, 2 rãnh thoát nước dọc 2 cạnh dài 0.5x0.5cm cách mép 1.5cm, rãnh cắt hết, vạt mép cạnh dài 3mm, KT 100x30x3, Đóng gói 35V | C107: Bazan đen | D107: Đá nắp tường rào | E107: Mặt đốt xịt nước, 2 cạnh dài hon, 2 rãnh thoát nước dọc 2 cạnh dài 0.5x0.5cm cách mép 1.5cm, rãnh cắt hết, vạt mép cạnh dài 3mm | F107: 100 | G107: 30 | H107: 3 | I107: 35
A108: BD080831205 | B108: Đá nắp tường rào Bazan đen, Mặt đốt xịt nước, 2 cạnh dài hon, 2 rãnh thoát nước dọc 2 cạnh dài 0.5x0.5cm cách mép 1.5cm, vạt 4 mép cạnh dài 3mm, KT 100x30x4, Đóng gói 25V | C108: Bazan đen | D108: Đá nắp tường rào | E108: Mặt đốt xịt nước, 2 cạnh dài hon, 2 rãnh thoát nước dọc 2 cạnh dài 0.5x0.5cm cách mép 1.5cm, vạt 4 mép cạnh dài 3mm | F108: 100 | G108: 30 | H108: 4 | I108: 25
...
